Workbook

Sheet 予選順位入力
A1: Pos. | B1: Pilot | C1: Time | E1: ← B列に予選順位どおりに Pilot 名を貼り付けてください。「決勝トーナメント自動入力シート」の1回戦に自動反映されます。
A2: 1 | E2: 各レースの左側の細い枠に着順(1〜4)を入力すると、次のレースの出走者が自動で埋まります。
A3: 2
A4: 3
A5: 4
A6: 5
A7: 6
A8: 7
A9: 8
A10: 9
A11: 10
A12: 11
A13: 12
A14: 13
... A33: 32

Sheet 決勝トーナメント自動入力シート
C1: １回戦 | L1: ２回戦 | U1: ３回戦 | AD1: ４回戦(B・C決勝戦) | AM1: ５回戦 | AV1: A決勝戦
AX4: B MAIN 8名
C5: Race1-1 | L5: Race2-1 | AD5: Race4-1
C6: =IF(予選順位入力!$B$18="","",予選順位入力!$B$18) | D6: １・２位 | L6: =IFERROR(INDEX($C$6:$C$9,MATCH(1,$B$6:$B$9,0)),"") | M6: １・２位 | AD6: =IFERROR(INDEX($L$6:$L$9,MATCH(1,$K$6:$K$9,0)),"")
C7: =IF(予選順位入力!$B$20="","",予選順位入力!$B$20) | L7: =IFERROR(INDEX($C$6:$C$9,MATCH(2,$B$6:$B$9,0)),"") | AD7: =IFERROR(INDEX($L$6:$L$9,MATCH(2,$K$6:$K$9,0)),"")
C8: =IF(予選順位入力!$B$22="","",予選順位入力!$B$22) | D8: ３・４位 | L8: =IFERROR(INDEX($C$12:$C$15,MATCH(1,$B$12:$B$15,0)),"") | M8: ３・４位 | AD8: =IFERROR(INDEX($U$12:$U$15,MATCH(1,$T$12:$T$15,0)),"")
C9: =IF(予選順位入力!$B$24="","",予選順位入力!$B$24) | L9: =IFERROR(INDEX($C$12:$C$15,MATCH(2,$B$12:$B$15,0)),"") | AD9: =IFERROR(INDEX($U$12:$U$15,MATCH(2,$T$12:$T$15,0)),"")
C11: Race1-2 | L11: Race2-2 | U11: Race3-1
C12: =IF(予選順位入力!$B$19="","",予選順位入力!$B$19) | D12: １・２位 | L12: =IFERROR(INDEX($C$6:$C$9,MATCH(4,$B$6:$B$9,0)),"") | M12: １・２位 | U12: =IFERROR(INDEX($L$6:$L$9,MATCH(3,$K$6:$K$9,0)),"") | V12: １・２位
C13: =IF(予選順位入力!$B$21="","",予選順位入力!$B$21) | L13: =IFERROR(INDEX($C$6:$C$9,MATCH(3,$B$6:$B$9,0)),"") | U13: =IFERROR(INDEX($L$6:$L$9,MATCH(4,$K$6:$K$9,0)),"")
C14: =IF(予選順位入力!$B$23="","",予選順位入力!$B$23) | D14: ３・４位 | L14: =IFERROR(INDEX($C$12:$C$15,MATCH(3,$B$12:$B$15,0)),"") | U14: =IFERROR(INDEX($L$12:$L$15,MATCH(1,$K$12:$K$15,0)),"")
C15: =IF(予選順位入力!$B$25="","",予選順位入力!$B$25) | L15: =IFERROR(INDEX($C$12:$C$15,MATCH(4,$B$12:$B$15,0)),"") | U15: =IFERROR(INDEX($L$12:$L$15,MATCH(2,$K$12:$K$15,0)),"")
AX18: C MAIN 7・8名
C19: Race1-3 | L19: Race2-3 | AD19: Race4-2
C20: =IF(予選順位入力!$B$26="","",予選順位入力!$B$26) | D20: １・２位 | L20: =IFERROR(INDEX($C$20:$C$23,MATCH(1,$B$20:$B$23,0)),"") | M20: １・２位 | AD20: =IFERROR(INDEX($L$20:$L$23,MATCH(1,$K$20:$K$23,0)),"")
C21: =IF(予選順位入力!$B$28="","",予選順位入力!$B$28) | L21: =IFERROR(INDEX($C$20:$C$23,MATCH(2,$B$20:$B$23,0)),"") | AD21: =IFERROR(INDEX($L$20:$L$23,MATCH(2,$K$20:$K$23,0)),"")
C22: =IF(予選順位入力!$B$30="","",予選順位入力!$B$30) | D22: ３・４位 | L22: =IFERROR(INDEX($C$26:$C$29,MATCH(1,$B$26:$B$29,0)),"") | M22: ３・４位 | AD22: =IFERROR(INDEX($U$26:$U$29,MATCH(1,$T$26:$T$29,0)),"")
C23: =IF(予選順位入力!$B$32="","",予選順位入力!$B$32) | L23: =IFERROR(INDEX($C$26:$C$29,MATCH(2,$B$26:$B$29,0)),"") | AD23: =IFERROR(INDEX($U$26:$U$29,MATCH(2,$T$26:$T$29,0)),"")
C25: Race1-4 | L25: Race2-4 | U25: Race3-2
C26: =IF(予選順位入力!$B$27="","",予選順位入力!$B$27) | D26: １・２位 | L26: =IFERROR(INDEX($C$20:$C$23,MATCH(4,$B$20:$B$23,0)),"") | M26: １・２位 | U26: =IFERROR(INDEX($L$20:$L$23,MATCH(3,$K$20:$K$23,0)),"") | V26: １・２位
C27: =IF(予選順位入力!$B$29="","",予選順位入力!$B$29) | L27: =IFERROR(INDEX($C$20:$C$23,MATCH(3,$B$20:$B$23,0)),"") | U27: =IFERROR(INDEX($L$20:$L$23,MATCH(4,$K$20:$K$23,0)),"")
C28: =IF(予選順位入力!$B$31="","",予選順位入力!$B$31) | D28: ３・４位 | L28: =IFERROR(INDEX($C$26:$C$29,MATCH(3,$B$26:$B$29,0)),"") | U28: =IFERROR(INDEX($L$26:$L$29,MATCH(1,$K$26:$K$29,0)),"")
C29: =IF(予選順位入力!$B$33="","",予選順位入力!$B$33) | L29: =IFERROR(INDEX($C$26:$C$29,MATCH(4,$B$26:$B$29,0)),"") | U29: =IFERROR(INDEX($L$26:$L$29,MATCH(2,$K$26:$K$29,0)),"")
AX32: A MAIN 16名
C33: Race1-5 | L33: Race2-5 | U33: Race3-3 | AV33: Race6-1
C34: =IF(予選順位入力!$B$2="","",予選順位入力!$B$2) | D34: １・２位 | L34: =IFERROR(INDEX($C$34:$C$37,MATCH(1,$B$34:$B$37,0)),"") | M34: １・２位 | U34: =IFERROR(INDEX($L$34:$L$37,MATCH(1,$K$34:$K$37,0)),"") | V34: １・２位 | AV34: =IFERROR(INDEX($U$34:$U$37,MATCH(1,$T$34:$T$37,0)),"")
C35: =IF(予選順位入力!$B$9="","",予選順位入力!$B$9) | L35: =IFERROR(INDEX($C$34:$C$37,MATCH(2,$B$34:$B$37,0)),"") | U35: =IFERROR(INDEX($L$34:$L$37,MATCH(2,$K$34:$K$37,0)),"") | AV35: =IFERROR(INDEX($U$34:$U$37,MATCH(2,$T$34:$T$37,0)),"")
C36: =IF(予選順位入力!$B$10="","",予選順位入力!$B$10) | D36: ３・４位 | L36: =IFERROR(INDEX($C$40:$C$43,MATCH(1,$B$40:$B$43,0)),"") | M36: ３・４位 | U36: =IFERROR(INDEX($L$40:$L$43,MATCH(1,$K$40:$K$43,0)),"") | V36: ３・４位 | AV36: =IFERROR(INDEX($AM$40:$AM$43,MATCH(1,$AL$40:$AL$43,0)),"")
C37: =IF(予選順位入力!$B$17="","",予選順位入力!$B$17) | L37: =IFERROR(INDEX($C$40:$C$43,MATCH(2,$B$40:$B$43,0)),"") | U37: =IFERROR(INDEX($L$40:$L$43,MATCH(2,$K$40:$K$43,0)),"") | AV37: =IFERROR(INDEX($AM$40:$AM$43,MATCH(2,$AL$40:$AL$43,0)),"")
C39: Race1-6 | L39: Race2-6 | AM39: Race5-1
C40: =IF(予選順位入力!$B$5="","",予選順位入力!$B$5) | D40: １・２位 | L40: =IFERROR(INDEX($C$46:$C$49,MATCH(1,$B$46:$B$49,0)),"") | M40: １・２位 | AM40: =IFERROR(INDEX($U$34:$U$37,MATCH(3,$T$34:$T$37,0)),"") | AN40: １・２位
C41: =IF(予選順位入力!$B$6="","",予選順位入力!$B$6) | L41: =IFERROR(INDEX($C$46:$C$49,MATCH(2,$B$46:$B$49,0)),"") | AM41: =IFERROR(INDEX($U$34:$U$37,MATCH(4,$T$34:$T$37,0)),"")
C42: =IF(予選順位入力!$B$13="","",予選順位入力!$B$13) | D42: ３・４位 | L42: =IFERROR(INDEX($C$52:$C$55,MATCH(1,$B$52:$B$55,0)),"") | M42: ３・４位 | AM42: =IFERROR(INDEX($AD$46:$AD$49,MATCH(1,$AC$46:$AC$49,0)),"")
C43: =IF(予選順位入力!$B$14="","",予選順位入力!$B$14) | L43: =IFERROR(INDEX($C$52:$C$55,MATCH(2,$B$52:$B$55,0)),"") | AM43: =IFERROR(INDEX($AD$46:$AD$49,MATCH(2,$AC$46:$AC$49,0)),"")
C45: Race1-7 | L45: Race2-7 | U45: Race3-4 | AD45: Race4-3
C46: =IF(予選順位入力!$B$4="","",予選順位入力!$B$4) | D46: １・２位 | L46: =IFERROR(INDEX($C$34:$C$37,MATCH(4,$B$34:$B$37,0)),"") | M46: １・２位 | U46: =IFERROR(INDEX($L$34:$L$37,MATCH(4,$K$34:$K$37,0)),"") | V46: １・２位 | AD46: =IFERROR(INDEX($U$46:$U$49,MATCH(1,$T$46:$T$49,0)),"") | AE46: １・２位
C47: =IF(予選順位入力!$B$7="","",予選順位入力!$B$7) | L47: =IFERROR(INDEX($C$40:$C$43,MATCH(3,$B$40:$B$43,0)),"") | U47: =IFERROR(INDEX($L$40:$L$43,MATCH(3,$K$40:$K$43,0)),"") | AD47: =IFERROR(INDEX($U$46:$U$49,MATCH(2,$T$46:$T$49,0)),"")
C48: =IF(予選順位入力!$B$11="","",予選順位入力!$B$11) | D48: ３・４位 | L48: =IFERROR(INDEX($C$46:$C$49,MATCH(3,$B$46:$B$49,0)),"") | U48: =IFERROR(INDEX($L$46:$L$49,MATCH(2,$K$46:$K$49,0)),"") | AD48: =IFERROR(INDEX($U$52:$U$55,MATCH(1,$T$52:$T$55,0)),"")
C49: =IF(予選順位入力!$B$15="","",予選順位入力!$B$15) | L49: =IFERROR(INDEX($C$52:$C$55,MATCH(4,$B$52:$B$55,0)),"") | U49: =IFERROR(INDEX($L$52:$L$55,MATCH(1,$K$52:$K$55,0)),"") | AD49: =IFERROR(INDEX($U$52:$U$55,MATCH(2,$T$52:$T$55,0)),"")
C51: Race1-8 | L51: Race2-8 | U51: Race3-5
...

Sheet 決勝トーナメント(印刷配布掲示用）
C1: １回戦 | L1: ２回戦 | U1: ３回戦 | AD1: ４回戦(B・C決勝戦) | AM1: ５回戦 | AV1: A決勝戦
AX4: B MAIN 8名
C5: Race1-1 | L5: Race2-1 | AD5: Race4-1
C6: 予選17位 | D6: １・２位 | L6: R1-1 １位 | M6: １・２位 | AD6: R2-1 １位
C7: 予選19位 | L7: R1-1 ２位 | AD7: R2-1 ２位
C8: 予選21位 | D8: ３・４位 | L8: R1-2 １位 | M8: ３・４位 | AD8: R3-1 １位
C9: 予選23位 | L9: R1-2 ２位 | AD9: R3-1 ２位
C11: Race1-2 | L11: Race2-2 | U11: Race3-1
C12: 予選18位 | D12: １・２位 | L12: R1-1 ４位 | M12: １・２位 | U12: R2-1 ３位 | V12: １・２位
C13: 予選20位 | L13: R1-1 ３位 | U13: R2-1 ４位
C14: 予選22位 | D14: ３・４位 | L14: R1-2 ３位 | U14: R2-2 １位
C15: 予選24位 | L15: R1-2 ４位 | U15: R2-2 ２位
AX18: C MAIN 7・8名
C19: Race1-3 | L19: Race2-3 | AD19: Race4-2
C20: 予選25位 | D20: １・２位 | L20: R1-3 １位 | M20: １・２位 | AD20: R2-3 １位
C21: 予選27位 | L21: R1-3 ２位 | AD21: R2-3 ２位
C22: 予選29位 | D22: ３・４位 | L22: R1-4 １位 | M22: ３・４位 | AD22: R3-2 １位
C23: 予選31位 | L23: R1-4 ２位 | AD23: R3-2 ２位
C25: Race1-4 | L25: Race2-4 | U25: Race3-2
C26: 予選26位 | D26: １・２位 | L26: R1-3 ４位 | M26: １・２位 | U26: R2-3 ３位 | V26: １・２位
C27: 予選28位 | L27: R1-3 ３位 | U27: R2-3 ４位
C28: 予選30位 | D28: ３・４位 | L28: R1-4 ３位 | U28: R2-4 １位
C29: 予選32位 | L29: R1-4 ４位 | U29: R2-4 ２位
AX32: A MAIN 16名
C33: Race1-5 | L33: Race2-5 | U33: Race3-3 | AV33: Race6-1
C34: 予選1位 | D34: １・２位 | L34: R1-5 １位 | M34: １・２位 | U34: R2-5 １位 | V34: １・２位 | AV34: R3-3 １位
C35: 予選8位 | L35: R1-5 ２位 | U35: R2-5 ２位 | AV35: R3-3 ２位
C36: 予選9位 | D36: ３・４位 | L36: R1-6 １位 | M36: ３・４位 | U36: R2-6 １位 | V36: ３・４位 | AV36: R5-1 １位
C37: 予選16位 | L37: R1-6 ２位 | U37: R2-6 ２位 | AV37: R5-1 ２位
C39: Race1-6 | L39: Race2-6 | AM39: Race5-1
C40: 予選4位 | D40: １・２位 | L40: R1-7 １位 | M40: １・２位 | AM40: R3-3 ３位 | AN40: １・２位
C41: 予選5位 | L41: R1-7 ２位 | AM41: R3-3 ４位
C42: 予選12位 | D42: ３・４位 | L42: R1-8 １位 | M42: ３・４位 | AM42: R4-3 １位
C43: 予選13位 | L43: R1-8 ２位 | AM43: R4-3 ２位
C45: Race1-7 | L45: Race2-7 | U45: Race3-4 | AD45: Race4-3
C46: 予選3位 | D46: １・２位 | L46: R1-5 ４位 | M46: １・２位 | U46: R2-5 ４位 | V46: １・２位 | AD46: R3-4 １位 | AE46: １・２位
C47: 予選6位 | L47: R1-6 ３位 | U47: R2-6 ３位 | AD47: R3-4 ２位
C48: 予選10位 | D48: ３・４位 | L48: R1-7 ３位 | U48: R2-7 ２位 | AD48: R3-5 １位
C49: 予選14位 | L49: R1-8 ４位 | U49: R2-8 １位 | AD49: R3-5 ２位
C51: Race1-8 | L51: Race2-8 | U51: Race3-5
...
